Workbook

Sheet INPUT DATA
A1: AGE | C1: PHOTOPIC PUPIL | D1: SCOTOPIC PUPIL | E1: ANGLE ALPHA | F1: ANGLE KAPPA | G1: CORNEAL SPHERICAL ABERRATION 6mm (Z40) | H1: CORNEAL VERTICAL COMA 6mm | I1: CORNEAL HORIZONTAL COMA 6mm | J1: OCULAR PATHOLOGIES | K1: GRADE
A2: 67 | C2: 1.8 | D2: 3.5 | E2: 0.1 | F2: 0.25 | G2: 0.35 | H2: 0.06 | I2: 0.05 | J2: CORNEAL ENDOTHELIAL DISEASE | K2: 1 | N2: MALE
J3: DRY EYE DISEASE | K3: 1 | N3: FEMALE
A4: MONOFOCAL LENSES | B4: SPHERICAL MONOFOCAL IOL | C4: ZERO ASPHERIC MONOFOCAL IOL | D4: NEGATIVE ASPHERIC MONOFOCAL IOL
A5: PREDICTED DEPTH OF FOCUS (DIOPTRES) | B5: ='SPHERICAL MONOFOCAL'!W48 -> 1.39 | C5: ='ZERO ASPHERIC MONOFOCAL'!W48 -> 1.39 | D5: ='NEGATIVE ASPHERIC MONOFOCAL'!W48 -> 1.39 | N5: DIABETIC RETINOPATHY
A6: PREDICTED DEPTH OF FOCUS GRADE | B6: ='SPHERICAL MONOFOCAL'!V18 -> Functional intermediate, limited near | C6: ='ZERO ASPHERIC MONOFOCAL'!V18 -> Functional intermediate, limited near | D6: ='NEGATIVE ASPHERIC MONOFOCAL'!V18 -> Functional intermediate, limited near | N6: DRY EYE DISEASE
N7: CORNEAL ENDOTHELIAL DISEASE
A8: PREDICTED MTF max | B8: ='SPHERICAL MONOFOCAL'!W47/10 -> 0.52 | C8: ='ZERO ASPHERIC MONOFOCAL'!W47/10 -> 0.61 | D8: ='NEGATIVE ASPHERIC MONOFOCAL'!W47/10 -> 0.65 | N8: MACULAR PATHOLOGY
A9: PREDICTED VISUAL QUALITY GRADE | B9: ='SPHERICAL MONOFOCAL'!W28 -> Excellent visual quality in normal lighting; mild reduction may be noticed in very low-light conditions | C9: ='ZERO ASPHERIC MONOFOCAL'!W28 -> excellent visual quality across all lighting conditions | D9: ='NEGATIVE ASPHERIC MONOFOCAL'!W28 -> excellent visual quality across all lighting conditions | N9: GLAUCOMA
A10: REFRACTIVE STABILITY | B10: ='REFRACTIVE STABILLITY'!L2 -> No clinically significant pupil-dependent refractive shift expected | C10: ='REFRACTIVE STABILLITY'!L2 -> No clinically significant pupil-dependent refractive shift expected | D10: ='REFRACTIVE STABILLITY'!L2 -> No clinically significant pupil-dependent refractive shift expected
A11: PREDICTED DYSPHOTOPSIA SCORE ( /10) | B11: ='DYSPHOTOPSIA SCORES'!F21 -> 1.6 | C11: ='DYSPHOTOPSIA SCORES'!F20 -> 1.6 | D11: ='DYSPHOTOPSIA SCORES'!F19 -> 1.2
A12: PREDICTED PATIENT SATISFACTION SCORE | B12: =ROUND(MIN(0.78,MAX(0,(0.45*IF(B8>=0.5,1,IF(B8>=0.4,0.85,IF(B8>=0.3,0.65,0.35))))+(0.2*MIN(B5/1.75,1))+(0.2*(1-B11/10))+(0.15*IF(A2>55,1,0.95)))*(1-0.2*MIN(SUM($K$2:$K$6)/9,1))),2) -> 0.78 | C12: =ROUND(MIN(0.78,MAX(0,(0.45*IF(C8>=0.5,1,IF(C8>=0.4,0.85,IF(C8>=0.3,0.65,0.35))))+(0.2*MIN(C5/1.75,1))+(0.2*(1-C11/10))+(0.15*IF(A2>55,1,0.95)))*(1-0.2*MIN(SUM($K$2:$K$6)/9,1))),2) -> 0.78 | D12: =ROUND(MIN(0.78,MAX(0,(0.45*IF(D8>=0.5,1,IF(D8>=0.4,0.85,IF(D8>=0.3,0.65,0.35))))+(0.2*MIN(D5/1.75,1))+(0.2*(1-D11/10))+(0.15*IF(A2>55,1,0.95)))*(1-0.2*MIN(SUM($K$2:$K$6)/9,1))),2) -> 0.78 | N12: 1
N13: 2
A14: EXTENDED MONOFOCAL and EDOF LENSES | B14: EYHANCE | C14: RAYNER EMV | D14: VIVITY | N14: 3
A15: PREDICTED DEPTH OF FOCUS (DIOPTRES) | B15: =EYHANCE!W48 -> 1.83 | C15: ='RAYNER EMV'!W48 -> 1.66 | D15: =VIVITY!W48 -> 2.26
A16: PREDICTED DEPTH OF FOCUS GRADE | B16: =EYHANCE!V18 -> Good intermediate and near | C16: ='RAYNER EMV'!V18 -> Functional intermediate, limited near | D16: =VIVITY!V18 -> Excellent near performance
A18: PREDICTED MTF max | B18: =EYHANCE!W47/10 -> 0.56 | C18: ='RAYNER EMV'!W47/10 -> 0.49 | D18: =VIVITY!W47/10 -> 0.3
A19: PREDICTED VISUAL QUALITY GRADE | B19: =EYHANCE!W28 -> Excellent visual quality in normal lighting; mild reduction may be noticed in very low-light conditions | C19: ='RAYNER EMV'!W28 -> Very good visual quality in bright lighting; noticeable decline in low-light environments | D19: =VIVITY!W28 -> Functional visual quality in good lighting; significant deterioration expected in dim light
A20: REFRACTIVE STABILITY | B20: ='REFRACTIVE STABILLITY'!L5 -> Beware of myopic shift for distance in bright light / small pupil conditions | C20: ='REFRACTIVE STABILLITY'!L6 -> Possible hyperopic shift for distance in bright light / small pupil conditions | D20: ='REFRACTIVE STABILLITY'!L7 -> No clinically significant pupil-dependent refractive shift expected
A21: PREDICTED DYSPHOTOPSIA SCORE ( /10) | B21: ='DYSPHOTOPSIA SCORES'!F23 -> 3.2 | C21: ='DYSPHOTOPSIA SCORES'!F22 -> 2.9 | D21: ='DYSPHOTOPSIA SCORES'!F24 -> 4.5
A22: PREDICTED PATIENT SATISFACTION SCORE | B22: =ROUND(MIN(0.95,MAX(0,((0.22*IF(B18>=0.5,1,IF(B18>=0.4,0.85,IF(B18>=0.3,0.65,0.3))))+(0.48*MIN(B15/2.5,1))+(0.18*(1-B21/10))+(0.12*IF(B15>=1.8,1,IF(B15>=1.5,0.7,0.3))))*(1-0.35*MIN(SUM($K$2:$K$6)/9,1))*IF(ISNUMBER(SEARCH("No clinically significant pupil-dependent refractive shift expected",B20)),1,IF(ISNUMBER(SEARCH("Beware of myopic shift for distance in bright light / small pupil conditions",B20)),0.92,IF(ISNUMBER(SEARCH("Possible hyperopic shift for distance in bright light / small pupil conditions",B20)),0.92,IF(ISNUMBER(SEARCH("Chances of low-light myopia / night myopia likely",B20)),0.88,IF(ISNUMBER(SEARCH("Possible hyperopic shift in dim light / larger pupil conditions",B20)),0.89,IF(ISNUMBER(SEARCH("Consistent myopic shift tendency across lighting conditions",B20)),0.84,IF(ISNUMBER(SEARCH("Consistent hyperopic shift tendency across lighting conditions",B20)),0.84,IF(ISNUMBER(SEARCH("Lighting-dependent refractive behavior likely",B20)),0.8,1)))))))))),2) -> 0.69 | C22: =ROUND(MIN(0.95,MAX(0,((0.22*IF(C18>=0.5,1,IF(C18>=0.4,0.85,IF(C18>=0.3,0.65,0.3))))+(0.48*MIN(C15/2.5,1))+(0.18*(1-C21/10))+(0.12*IF(C15>=1.8,1,IF(C15>=1.5,0.7,0.3))))*(1-0.35*MIN(SUM($K$2:$K$6)/9,1))*IF(ISNUMBER(SEARCH("No clinically significant pupil-dependent refractive shift expected",C20)),1,IF(ISNUMBER(SEARCH("Beware of myopic shift for distance in bright light / small pupil conditions",C20)),0.92,IF(ISNUMBER(SEARCH("Possible hyperopic shift for distance in bright light / small pupil conditions",C20)),0.92,IF(ISNUMBER(SEARCH("Chances of low-light myopia / night myopia likely",C20)),0.88,IF(ISNUMBER(SEARCH("Possible hyperopic shift in dim light / larger pupil conditions",C20)),0.89,IF(ISNUMBER(SEARCH("Consistent myopic shift tendency across lighting conditions",C20)),0.84,IF(ISNUMBER(SEARCH("Consistent hyperopic shift tendency across lighting conditions",C20)),0.84,IF(ISNUMBER(SEARCH("Lighting-dependent refractive behavior likely",C20)),0.8,1)))))))))),2) -> 0.61 | D22: =ROUND(MIN(0.95,MAX(0,((0.22*IF(D18>=0.5,1,IF(D18>=0.4,0.85,IF(D18>=0.3,0.65,0.3))))+(0.48*MIN(D15/2.5,1))+(0.18*(1-D21/10))+(0.12*IF(D15>=1.8,1,IF(D15>=1.5,0.7,0.3))))*(1-0.35*MIN(SUM($K$2:$K$6)/9,1))*IF(ISNUMBER(SEARCH("No clinically significant pupil-dependent refractive shift expected",D20)),1,IF(ISNUMBER(SEARCH("Beware of myopic shift for distance in bright light / small pupil conditions",D20)),0.92,IF(ISNUMBER(SEARCH("Possible hyperopic shift for distance in bright light / small pupil conditions",D20)),0.92,IF(ISNUMBER(SEARCH("Chances of low-light myopia / night myopia likely",D20)),0.88,IF(ISNUMBER(SEARCH("Possible hyperopic shift in dim light / larger pupil conditions",D20)),0.89,IF(ISNUMBER(SEARCH("Consistent myopic shift tendency across lighting conditions",D20)),0.84,IF(ISNUMBER(SEARCH("Consistent hyperopic shift tendency across lighting conditions",D20)),0.84,IF(ISNUMBER(SEARCH("Lighting-dependent refractive behavior likely",D20)),0.8,1)))))))))),2) -> 0.73
A24: DIFFRACTIVE LENSES | B24: PANOPTIX | C24: GEMETRIC | D24: ATLISA TRI
A25: PREDICTED DEPTH OF FOCUS (DIOPTRES) | B25: =PANOPTIX!W48 -> 1.95 | C25: =GEMETRIC!W48 -> 1.61 | D25: ='ATLISA TRI'!W48 -> 1.69
A26: PREDICTED DEPTH OF FOCUS GRADE | B26: =PANOPTIX!V21 -> Good intermediate and near | C26: =GEMETRIC!V21 -> Functional intermediate, limited near | D26: ='ATLISA TRI'!V21 -> Functional intermediate, limited near
A28: PREDICTED MTF max | B28: =PANOPTIX!W47/10 -> 0.45 | C28: =GEMETRIC!W47/10 -> 0.44 | D28: ='ATLISA TRI'!W47/10 -> 0.47
A29: PREDICTED VISUAL QUALITY GRADE | B29: =PANOPTIX!V27 -> Very good visual quality in bright lighting; noticeable decline in low-light environments | C29: =GEMETRIC!V27 -> Very good visual quality in bright lighting; noticeable decline in low-light environments | D29: ='ATLISA TRI'!V27 -> Very good visual quality in bright lighting; noticeable decline in low-light environments
A30: REFRACTIVE STABILITY | B30: ='REFRACTIVE STABILLITY'!L2 -> No clinically significant pupil-dependent refractive shift expected | C30: ='REFRACTIVE STABILLITY'!L2 -> No clinically significant pupil-dependent refractive shift expected | D30: ='REFRACTIVE STABILLITY'!L2 -> No clinically significant pupil-dependent refractive shift expected
A31: PREDICTED DYSPHOTOPSIA SCORE ( /10) | B31: ='DYSPHOTOPSIA SCORES'!F27 -> 6.4 | C31: ='DYSPHOTOPSIA SCORES'!F25 -> 5.8 | D31: ='DYSPHOTOPSIA SCORES'!F26 -> 6.2
A32: PREDICTED PATIENT SATISFACTION SCORE | B32: =ROUND(MIN(0.95,MAX(0,((0.22*IF(B28>=0.5,1,IF(B28>=0.4,0.85,IF(B28>=0.3,0.65,0.3))))+(0.48*MIN(B25/2.5,1))+(0.18*(1-B31/10))+(0.12*IF(B25>=1.8,1,IF(B25>=1.5,0.7,0.3))))*(1-0.35*MIN(SUM($K$2:$K$6)/9,1)))),2) -> 0.69 | C32: =ROUND(MIN(0.95,MAX(0,((0.22*IF(C28>=0.5,1,IF(C28>=0.4,0.85,IF(C28>=0.3,0.65,0.3))))+(0.48*MIN(C25/2.5,1))+(0.18*(1-C31/10))+(0.12*IF(C25>=1.8,1,IF(C25>=1.5,0.7,0.3))))*(1-0.35*MIN(SUM($K$2:$K$6)/9,1)))),2) -> 0.6 | D32: =ROUND(MIN(0.95,MAX(0,((0.22*IF(D28>=0.5,1,IF(D28>=0.4,0.85,IF(D28>=0.3,0.65,0.3))))+(0.48*MIN(D25/2.5,1))+(0.18*(1-D31/10))+(0.12*IF(D25>=1.8,1,IF(D25>=1.5,0.7,0.3))))*(1-0.35*MIN(SUM($K$2:$K$6)/9,1)))),2) -> 0.61

Sheet REFRACTIVE STABILLITY
D1: PH P | E1: SC P | H1: CORNEAL SA
B2: SPHERICAL MONOFOCAL IOL | D2: ='INPUT DATA'!C2 -> 1.8 | E2: ='INPUT DATA'!D2 -> 3.5 | H2: ='INPUT DATA'!G2 -> 0.35 | J2: =IF(OR(B2=$B$2,B2=$B$3,B2=$B$4,B2=$B$8,B2=$B$9,B2=$B$10),0, IF(B2=$B$5,INDEX($R$4:$T$7,MATCH(IF($D$2<2.5,2,IF($D$2<3.5,3,IF($D$2<4.5,4,5))),$O$4:$O$7,0),MATCH(IF($H$2<=0,"0 AND LESS",IF($H$2<0.4,"0.1 TO 0.3","0.4 AND ABOVE")),$R$3:$T$3,0)), IF(B2=$B$6,INDEX($R$11:$T$14,MATCH(IF($D$2<2.5,2,IF($D$2<3.5,3,IF($D$2<4.5,4,5))),$O$11:$O$14,0),MATCH(IF($H$2<=0,"0 AND LESS",IF($H$2<0.4,"0.1 TO 0.3","0.4 AND ABOVE")),$R$10:$T$10,0)), IF(B2=$B$7,INDEX($R$18:$T$21,MATCH(IF($D$2<2.5,2,IF($D$2<3.5,3,IF($D$2<4.5,4,5))),$O$18:$O$21,0),MATCH(IF($H$2<=0,"0 AND LESS",IF($H$2<0.4,"0.1 TO 0.3","0.4 AND ABOVE")),$R$17:$T$17,0)),0)))) -> 0 | K2: =IF(OR(B2=$B$2,B2=$B$3,B2=$B$4,B2=$B$8,B2=$B$9,B2=$B$10),0, IF(B2=$B$5,INDEX($R$4:$T$7,MATCH(IF($E$2<2.5,2,IF($E$2<3.5,3,IF($E$2<4.5,4,5))),$O$4:$O$7,0),MATCH(IF($H$2<=0,"0 AND LESS",IF($H$2<0.4,"0.1 TO 0.3","0.4 AND ABOVE")),$R$3:$T$3,0)), IF(B2=$B$6,INDEX($R$11:$T$14,MATCH(IF($E$2<2.5,2,IF($E$2<3.5,3,IF($E$2<4.5,4,5))),$O$11:$O$14,0),MATCH(IF($H$2<=0,"0 AND LESS",IF($H$2<0.4,"0.1 TO 0.3","0.4 AND ABOVE")),$R$10:$T$10,0)), IF(B2=$B$7,INDEX($R$18:$T$21,MATCH(IF($E$2<2.5,2,IF($E$2<3.5,3,IF($E$2<4.5,4,5))),$O$18:$O$21,0),MATCH(IF($H$2<=0,"0 AND LESS",IF($H$2<0.4,"0.1 TO 0.3","0.4 AND ABOVE")),$R$17:$T$17,0)),0)))) -> 0 | L2: =IF(AND(ABS(J2)<0.5,ABS(K2)<0.5), "No clinically significant pupil-dependent refractive shift expected", IF(AND(J2<=-0.5,ABS(K2)<0.5), "Beware of myopic shift for distance in bright light / small pupil conditions", IF(AND(J2>=0.5,ABS(K2)<0.5), "Possible hyperopic shift for distance in bright light / small pupil conditions", IF(AND(ABS(J2)<0.5,K2<=-0.5), "Chances of low-light myopia / night myopia likely", IF(AND(ABS(J2)<0.5,K2>=0.5), "Possible hyperopic shift in dim light / larger pupil conditions", IF(AND(J2<=-0.5,K2<=-0.5), "Consistent myopic shift tendency across lighting conditions", IF(AND(J2>=0.5,K2>=0.5), "Consistent hyperopic shift tendency across lighting conditions", IF(AND(J2<=-0.5,K2>=0.5), "Lighting-dependent refractive behavior likely, with myopic tendency in bright light and hyperopic tendency in dim light", IF(AND(J2>=0.5,K2<=-0.5), "Lighting-dependent refractive behavior likely, with hyperopic tendency in bright light and night myopia in dim light", "No clinically significant pupil-dependent refractive shift expected"))))))))) -> No clinically significant pupil-dependent refractive shift expected | N2: EYHANCE | R2: CORNEAL SA
B3: ZERO ASPHERIC MONOFOCAL IOL | J3: =IF(OR(B3=$B$2,B3=$B$3,B3=$B$4,B3=$B$8,B3=$B$9,B3=$B$10),0, IF(B3=$B$5,INDEX($R$4:$T$7,MATCH(IF($D$2<2.5,2,IF($D$2<3.5,3,IF($D$2<4.5,4,5))),$O$4:$O$7,0),MATCH(IF($H$2<=0,"0 AND LESS",IF($H$2<0.4,"0.1 TO 0.3","0.4 AND ABOVE")),$R$3:$T$3,0)), IF(B3=$B$6,INDEX($R$11:$T$14,MATCH(IF($D$2<2.5,2,IF($D$2<3.5,3,IF($D$2<4.5,4,5))),$O$11:$O$14,0),MATCH(IF($H$2<=0,"0 AND LESS",IF($H$2<0.4,"0.1 TO 0.3","0.4 AND ABOVE")),$R$10:$T$10,0)), IF(B3=$B$7,INDEX($R$18:$T$21,MATCH(IF($D$2<2.5,2,IF($D$2<3.5,3,IF($D$2<4.5,4,5))),$O$18:$O$21,0),MATCH(IF($H$2<=0,"0 AND LESS",IF($H$2<0.4,"0.1 TO 0.3","0.4 AND ABOVE")),$R$17:$T$17,0)),0)))) -> 0 | K3: =IF(OR(B3=$B$2,B3=$B$3,B3=$B$4,B3=$B$8,B3=$B$9,B3=$B$10),0, IF(B3=$B$5,INDEX($R$4:$T$7,MATCH(IF($E$2<2.5,2,IF($E$2<3.5,3,IF($E$2<4.5,4,5))),$O$4:$O$7,0),MATCH(IF($H$2<=0,"0 AND LESS",IF($H$2<0.4,"0.1 TO 0.3","0.4 AND ABOVE")),$R$3:$T$3,0)), IF(B3=$B$6,INDEX($R$11:$T$14,MATCH(IF($E$2<2.5,2,IF($E$2<3.5,3,IF($E$2<4.5,4,5))),$O$11:$O$14,0),MATCH(IF($H$2<=0,"0 AND LESS",IF($H$2<0.4,"0.1 TO 0.3","0.4 AND ABOVE")),$R$10:$T$10,0)), IF(B3=$B$7,INDEX($R$18:$T$21,MATCH(IF($E$2<2.5,2,IF($E$2<3.5,3,IF($E$2<4.5,4,5))),$O$18:$O$21,0),MATCH(IF($H$2<=0,"0 AND LESS",IF($H$2<0.4,"0.1 TO 0.3","0.4 AND ABOVE")),$R$17:$T$17,0)),0)))) -> 0 | L3: =IF(AND(ABS(J3)<0.5,ABS(K3)<0.5), "No clinically significant pupil-dependent refractive shift expected", IF(AND(J3<=-0.5,ABS(K3)<0.5), "Beware of myopic shift for distance in bright light / small pupil conditions", IF(AND(J3>=0.5,ABS(K3)<0.5), "Possible hyperopic shift for distance in bright light / small pupil conditions", IF(AND(ABS(J3)<0.5,K3<=-0.5), "Chances of low-light myopia / night myopia likely", IF(AND(ABS(J3)<0.5,K3>=0.5), "Possible hyperopic shift in dim light / larger pupil conditions", IF(AND(J3<=-0.5,K3<=-0.5), "Consistent myopic shift tendency across lighting conditions", IF(AND(J3>=0.5,K3>=0.5), "Consistent hyperopic shift tendency across lighting conditions", IF(AND(J3<=-0.5,K3>=0.5), "Lighting-dependent refractive behavior likely, with myopic tendency in bright light and hyperopic tendency in dim light", IF(AND(J3>=0.5,K3<=-0.5), "Lighting-dependent refractive behavior likely, with hyperopic tendency in bright light and night myopia in dim light", "No clinically significant pupil-dependent refractive shift expected"))))))))) -> No clinically significant pupil-dependent refractive shift expected | O3: PUPIL SIZE | P3: REFRACTIVE EFFECT | R3: 0 AND LESS | S3: 0.1 TO 0.3 | T3: 0.4 AND ABOVE
B4: NEGATIVE ASPHERIC MONOFOCAL IOL | J4: =IF(OR(B4=$B$2,B4=$B$3,B4=$B$4,B4=$B$8,B4=$B$9,B4=$B$10),0, IF(B4=$B$5,INDEX($R$4:$T$7,MATCH(IF($D$2<2.5,2,IF($D$2<3.5,3,IF($D$2<4.5,4,5))),$O$4:$O$7,0),MATCH(IF($H$2<=0,"0 AND LESS",IF($H$2<0.4,"0.1 TO 0.3","0.4 AND ABOVE")),$R$3:$T$3,0)), IF(B4=$B$6,INDEX($R$11:$T$14,MATCH(IF($D$2<2.5,2,IF($D$2<3.5,3,IF($D$2<4.5,4,5))),$O$11:$O$14,0),MATCH(IF($H$2<=0,"0 AND LESS",IF($H$2<0.4,"0.1 TO 0.3","0.4 AND ABOVE")),$R$10:$T$10,0)), IF(B4=$B$7,INDEX($R$18:$T$21,MATCH(IF($D$2<2.5,2,IF($D$2<3.5,3,IF($D$2<4.5,4,5))),$O$18:$O$21,0),MATCH(IF($H$2<=0,"0 AND LESS",IF($H$2<0.4,"0.1 TO 0.3","0.4 AND ABOVE")),$R$17:$T$17,0)),0)))) -> 0 | K4: =IF(OR(B4=$B$2,B4=$B$3,B4=$B$4,B4=$B$8,B4=$B$9,B4=$B$10),0, IF(B4=$B$5,INDEX($R$4:$T$7,MATCH(IF($E$2<2.5,2,IF($E$2<3.5,3,IF($E$2<4.5,4,5))),$O$4:$O$7,0),MATCH(IF($H$2<=0,"0 AND LESS",IF($H$2<0.4,"0.1 TO 0.3","0.4 AND ABOVE")),$R$3:$T$3,0)), IF(B4=$B$6,INDEX($R$11:$T$14,MATCH(IF($E$2<2.5,2,IF($E$2<3.5,3,IF($E$2<4.5,4,5))),$O$11:$O$14,0),MATCH(IF($H$2<=0,"0 AND LESS",IF($H$2<0.4,"0.1 TO 0.3","0.4 AND ABOVE")),$R$10:$T$10,0)), IF(B4=$B$7,INDEX($R$18:$T$21,MATCH(IF($E$2<2.5,2,IF($E$2<3.5,3,IF($E$2<4.5,4,5))),$O$18:$O$21,0),MATCH(IF($H$2<=0,"0 AND LESS",IF($H$2<0.4,"0.1 TO 0.3","0.4 AND ABOVE")),$R$17:$T$17,0)),0)))) -> 0 | L4: =IF(AND(ABS(J4)<0.5,ABS(K4)<0.5), "No clinically significant pupil-dependent refractive shift expected", IF(AND(J4<=-0.5,ABS(K4)<0.5), "Beware of myopic shift for distance in bright light / small pupil conditions", IF(AND(J4>=0.5,ABS(K4)<0.5), "Possible hyperopic shift for distance in bright light / small pupil conditions", IF(AND(ABS(J4)<0.5,K4<=-0.5), "Chances of low-light myopia / night myopia likely", IF(AND(ABS(J4)<0.5,K4>=0.5), "Possible hyperopic shift in dim light / larger pupil conditions", IF(AND(J4<=-0.5,K4<=-0.5), "Consistent myopic shift tendency across lighting conditions", IF(AND(J4>=0.5,K4>=0.5), "Consistent hyperopic shift tendency across lighting conditions", IF(AND(J4<=-0.5,K4>=0.5), "Lighting-dependent refractive behavior likely, with myopic tendency in bright light and hyperopic tendency in dim light", IF(AND(J4>=0.5,K4<=-0.5), "Lighting-dependent refractive behavior likely, with hyperopic tendency in bright light and night myopia in dim light", "No clinically significant pupil-dependent refractive shift expected"))))))))) -> No clinically significant pupil-dependent refractive shift expected | O4: 2 | R4: -0.5 | S4: -0.75 | T4: -0.75
B5: EYHANCE | J5: =IF(OR(B5=$B$2,B5=$B$3,B5=$B$4,B5=$B$8,B5=$B$9,B5=$B$10),0, IF(B5=$B$5,INDEX($R$4:$T$7,MATCH(IF($D$2<2.5,2,IF($D$2<3.5,3,IF($D$2<4.5,4,5))),$O$4:$O$7,0),MATCH(IF($H$2<=0,"0 AND LESS",IF($H$2<0.4,"0.1 TO 0.3","0.4 AND ABOVE")),$R$3:$T$3,0)), IF(B5=$B$6,INDEX($R$11:$T$14,MATCH(IF($D$2<2.5,2,IF($D$2<3.5,3,IF($D$2<4.5,4,5))),$O$11:$O$14,0),MATCH(IF($H$2<=0,"0 AND LESS",IF($H$2<0.4,"0.1 TO 0.3","0.4 AND ABOVE")),$R$10:$T$10,0)), IF(B5=$B$7,INDEX($R$18:$T$21,MATCH(IF($D$2<2.5,2,IF($D$2<3.5,3,IF($D$2<4.5,4,5))),$O$18:$O$21,0),MATCH(IF($H$2<=0,"0 AND LESS",IF($H$2<0.4,"0.1 TO 0.3","0.4 AND ABOVE")),$R$17:$T$17,0)),0)))) -> -0.75 | K5: =IF(OR(B5=$B$2,B5=$B$3,B5=$B$4,B5=$B$8,B5=$B$9,B5=$B$10),0, IF(B5=$B$5,INDEX($R$4:$T$7,MATCH(IF($E$2<2.5,2,IF($E$2<3.5,3,IF($E$2<4.5,4,5))),$O$4:$O$7,0),MATCH(IF($H$2<=0,"0 AND LESS",IF($H$2<0.4,"0.1 TO 0.3","0.4 AND ABOVE")),$R$3:$T$3,0)), IF(B5=$B$6,INDEX($R$11:$T$14,MATCH(IF($E$2<2.5,2,IF($E$2<3.5,3,IF($E$2<4.5,4,5))),$O$11:$O$14,0),MATCH(IF($H$2<=0,"0 AND LESS",IF($H$2<0.4,"0.1 TO 0.3","0.4 AND ABOVE")),$R$10:$T$10,0)), IF(B5=$B$7,INDEX($R$18:$T$21,MATCH(IF($E$2<2.5,2,IF($E$2<3.5,3,IF($E$2<4.5,4,5))),$O$18:$O$21,0),MATCH(IF($H$2<=0,"0 AND LESS",IF($H$2<0.4,"0.1 TO 0.3","0.4 AND ABOVE")),$R$17:$T$17,0)),0)))) -> 0 | L5: =IF(AND(ABS(J5)<0.5,ABS(K5)<0.5), "No clinically significant pupil-dependent refractive shift expected", IF(AND(J5<=-0.5,ABS(K5)<0.5), "Beware of myopic shift for distance in bright light / small pupil conditions", IF(AND(J5>=0.5,ABS(K5)<0.5), "Possible hyperopic shift for distance in bright light / small pupil conditions", IF(AND(ABS(J5)<0.5,K5<=-0.5), "Chances of low-light myopia / night myopia likely", IF(AND(ABS(J5)<0.5,K5>=0.5), "Possible hyperopic shift in dim light / larger pupil conditions", IF(AND(J5<=-0.5,K5<=-0.5), "Consistent myopic shift tendency across lighting conditions", IF(AND(J5>=0.5,K5>=0.5), "Consistent hyperopic shift tendency across lighting conditions", IF(AND(J5<=-0.5,K5>=0.5), "Lighting-dependent refractive behavior likely, with myopic tendency in bright light and hyperopic tendency in dim light", IF(AND(J5>=0.5,K5<=-0.5), "Lighting-dependent refractive behavior likely, with hyperopic tendency in bright light and night myopia in dim light", "No clinically significant pupil-dependent refractive shift expected"))))))))) -> Beware of myopic shift for distance in bright light / small pupil conditions | O5: 3 | R5: 0 | S5: -0.25 | T5: -0.5
B6: RAYNER EMV | J6: =IF(OR(B6=$B$2,B6=$B$3,B6=$B$4,B6=$B$8,B6=$B$9,B6=$B$10),0, IF(B6=$B$5,INDEX($R$4:$T$7,MATCH(IF($D$2<2.5,2,IF($D$2<3.5,3,IF($D$2<4.5,4,5))),$O$4:$O$7,0),MATCH(IF($H$2<=0,"0 AND LESS",IF($H$2<0.4,"0.1 TO 0.3","0.4 AND ABOVE")),$R$3:$T$3,0)), IF(B6=$B$6,INDEX($R$11:$T$14,MATCH(IF($D$2<2.5,2,IF($D$2<3.5,3,IF($D$2<4.5,4,5))),$O$11:$O$14,0),MATCH(IF($H$2<=0,"0 AND LESS",IF($H$2<0.4,"0.1 TO 0.3","0.4 AND ABOVE")),$R$10:$T$10,0)), IF(B6=$B$7,INDEX($R$18:$T$21,MATCH(IF($D$2<2.5,2,IF($D$2<3.5,3,IF($D$2<4.5,4,5))),$O$18:$O$21,0),MATCH(IF($H$2<=0,"0 AND LESS",IF($H$2<0.4,"0.1 TO 0.3","0.4 AND ABOVE")),$R$17:$T$17,0)),0)))) -> 0.5 | K6: =IF(OR(B6=$B$2,B6=$B$3,B6=$B$4,B6=$B$8,B6=$B$9,B6=$B$10),0, IF(B6=$B$5,INDEX($R$4:$T$7,MATCH(IF($E$2<2.5,2,IF($E$2<3.5,3,IF($E$2<4.5,4,5))),$O$4:$O$7,0),MATCH(IF($H$2<=0,"0 AND LESS",IF($H$2<0.4,"0.1 TO 0.3","0.4 AND ABOVE")),$R$3:$T$3,0)), IF(B6=$B$6,INDEX($R$11:$T$14,MATCH(IF($E$2<2.5,2,IF($E$2<3.5,3,IF($E$2<4.5,4,5))),$O$11:$O$14,0),MATCH(IF($H$2<=0,"0 AND LESS",IF($H$2<0.4,"0.1 TO 0.3","0.4 AND ABOVE")),$R$10:$T$10,0)), IF(B6=$B$7,INDEX($R$18:$T$21,MATCH(IF($E$2<2.5,2,IF($E$2<3.5,3,IF($E$2<4.5,4,5))),$O$18:$O$21,0),MATCH(IF($H$2<=0,"0 AND LESS",IF($H$2<0.4,"0.1 TO 0.3","0.4 AND ABOVE")),$R$17:$T$17,0)),0)))) -> 0 | L6: =IF(AND(ABS(J6)<0.5,ABS(K6)<0.5), "No clinically significant pupil-dependent refractive shift expected", IF(AND(J6<=-0.5,ABS(K6)<0.5), "Beware of myopic shift for distance in bright light / small pupil conditions", IF(AND(J6>=0.5,ABS(K6)<0.5), "Possible hyperopic shift for distance in bright light / small pupil conditions", IF(AND(ABS(J6)<0.5,K6<=-0.5), "Chances of low-light myopia / night myopia likely", IF(AND(ABS(J6)<0.5,K6>=0.5), "Possible hyperopic shift in dim light / larger pupil conditions", IF(AND(J6<=-0.5,K6<=-0.5), "Consistent myopic shift tendency across lighting conditions", IF(AND(J6>=0.5,K6>=0.5), "Consistent hyperopic shift tendency across lighting conditions", IF(AND(J6<=-0.5,K6>=0.5), "Lighting-dependent refractive behavior likely, with myopic tendency in bright light and hyperopic tendency in dim light", IF(AND(J6>=0.5,K6<=-0.5), "Lighting-dependent refractive behavior likely, with hyperopic tendency in bright light and night myopia in dim light", "No clinically significant pupil-dependent refractive shift expected"))))))))) -> Possible hyperopic shift for distance in bright light / small pupil conditions | O6: 4 | R6: 0.5 | S6: 0 | T6: -0.5
B7: VIVITY | J7: =IF(OR(B7=$B$2,B7=$B$3,B7=$B$4,B7=$B$8,B7=$B$9,B7=$B$10),0, IF(B7=$B$5,INDEX($R$4:$T$7,MATCH(IF($D$2<2.5,2,IF($D$2<3.5,3,IF($D$2<4.5,4,5))),$O$4:$O$7,0),MATCH(IF($H$2<=0,"0 AND LESS",IF($H$2<0.4,"0.1 TO 0.3","0.4 AND ABOVE")),$R$3:$T$3,0)), IF(B7=$B$6,INDEX($R$11:$T$14,MATCH(IF($D$2<2.5,2,IF($D$2<3.5,3,IF($D$2<4.5,4,5))),$O$11:$O$14,0),MATCH(IF($H$2<=0,"0 AND LESS",IF($H$2<0.4,"0.1 TO 0.3","0.4 AND ABOVE")),$R$10:$T$10,0)), IF(B7=$B$7,INDEX($R$18:$T$21,MATCH(IF($D$2<2.5,2,IF($D$2<3.5,3,IF($D$2<4.5,4,5))),$O$18:$O$21,0),MATCH(IF($H$2<=0,"0 AND LESS",IF($H$2<0.4,"0.1 TO 0.3","0.4 AND ABOVE")),$R$17:$T$17,0)),0)))) -> 0 | K7: =IF(OR(B7=$B$2,B7=$B$3,B7=$B$4,B7=$B$8,B7=$B$9,B7=$B$10),0, IF(B7=$B$5,INDEX($R$4:$T$7,MATCH(IF($E$2<2.5,2,IF($E$2<3.5,3,IF($E$2<4.5,4,5))),$O$4:$O$7,0),MATCH(IF($H$2<=0,"0 AND LESS",IF($H$2<0.4,"0.1 TO 0.3","0.4 AND ABOVE")),$R$3:$T$3,0)), IF(B7=$B$6,INDEX($R$11:$T$14,MATCH(IF($E$2<2.5,2,IF($E$2<3.5,3,IF($E$2<4.5,4,5))),$O$11:$O$14,0),MATCH(IF($H$2<=0,"0 AND LESS",IF($H$2<0.4,"0.1 TO 0.3","0.4 AND ABOVE")),$R$10:$T$10,0)), IF(B7=$B$7,INDEX($R$18:$T$21,MATCH(IF($E$2<2.5,2,IF($E$2<3.5,3,IF($E$2<4.5,4,5))),$O$18:$O$21,0),MATCH(IF($H$2<=0,"0 AND LESS",IF($H$2<0.4,"0.1 TO 0.3","0.4 AND ABOVE")),$R$17:$T$17,0)),0)))) -> -0.37 | L7: =IF(AND(ABS(J7)<0.5,ABS(K7)<0.5), "No clinically significant pupil-dependent refractive shift expected", IF(AND(J7<=-0.5,ABS(K7)<0.5), "Beware of myopic shift for distance in bright light / small pupil conditions", IF(AND(J7>=0.5,ABS(K7)<0.5), "Possible hyperopic shift for distance in bright light / small pupil conditions", IF(AND(ABS(J7)<0.5,K7<=-0.5), "Chances of low-light myopia / night myopia likely", IF(AND(ABS(J7)<0.5,K7>=0.5), "Possible hyperopic shift in dim light / larger pupil conditions", IF(AND(J7<=-0.5,K7<=-0.5), "Consistent myopic shift tendency across lighting conditions", IF(AND(J7>=0.5,K7>=0.5), "Consistent hyperopic shift tendency across lighting conditions", IF(AND(J7<=-0.5,K7>=0.5), "Lighting-dependent refractive behavior likely, with myopic tendency in bright light and hyperopic tendency in dim light", IF(AND(J7>=0.5,K7<=-0.5), "Lighting-dependent refractive behavior likely, with hyperopic tendency in bright light and night myopia in dim light", "No clinically significant pupil-dependent refractive shift expected"))))))))) -> No clinically significant pupil-dependent refractive shift expected | O7: 5 | R7: 0.5 | S7: 0 | T7: -0.5
B8: PANOPTIX | J8: =IF(OR(B8=$B$2,B8=$B$3,B8=$B$4,B8=$B$8,B8=$B$9,B8=$B$10),0, IF(B8=$B$5,INDEX($R$4:$T$7,MATCH(IF($D$2<2.5,2,IF($D$2<3.5,3,IF($D$2<4.5,4,5))),$O$4:$O$7,0),MATCH(IF($H$2<=0,"0 AND LESS",IF($H$2<0.4,"0.1 TO 0.3","0.4 AND ABOVE")),$R$3:$T$3,0)), IF(B8=$B$6,INDEX($R$11:$T$14,MATCH(IF($D$2<2.5,2,IF($D$2<3.5,3,IF($D$2<4.5,4,5))),$O$11:$O$14,0),MATCH(IF($H$2<=0,"0 AND LESS",IF($H$2<0.4,"0.1 TO 0.3","0.4 AND ABOVE")),$R$10:$T$10,0)), IF(B8=$B$7,INDEX($R$18:$T$21,MATCH(IF($D$2<2.5,2,IF($D$2<3.5,3,IF($D$2<4.5,4,5))),$O$18:$O$21,0),MATCH(IF($H$2<=0,"0 AND LESS",IF($H$2<0.4,"0.1 TO 0.3","0.4 AND ABOVE")),$R$17:$T$17,0)),0)))) -> 0 | K8: =IF(OR(B8=$B$2,B8=$B$3,B8=$B$4,B8=$B$8,B8=$B$9,B8=$B$10),0, IF(B8=$B$5,INDEX($R$4:$T$7,MATCH(IF($E$2<2.5,2,IF($E$2<3.5,3,IF($E$2<4.5,4,5))),$O$4:$O$7,0),MATCH(IF($H$2<=0,"0 AND LESS",IF($H$2<0.4,"0.1 TO 0.3","0.4 AND ABOVE")),$R$3:$T$3,0)), IF(B8=$B$6,INDEX($R$11:$T$14,MATCH(IF($E$2<2.5,2,IF($E$2<3.5,3,IF($E$2<4.5,4,5))),$O$11:$O$14,0),MATCH(IF($H$2<=0,"0 AND LESS",IF($H$2<0.4,"0.1 TO 0.3","0.4 AND ABOVE")),$R$10:$T$10,0)), IF(B8=$B$7,INDEX($R$18:$T$21,MATCH(IF($E$2<2.5,2,IF($E$2<3.5,3,IF($E$2<4.5,4,5))),$O$18:$O$21,0),MATCH(IF($H$2<=0,"0 AND LESS",IF($H$2<0.4,"0.1 TO 0.3","0.4 AND ABOVE")),$R$17:$T$17,0)),0)))) -> 0 | L8: =IF(AND(ABS(J8)<0.5,ABS(K8)<0.5), "No clinically significant pupil-dependent refractive shift expected", IF(AND(J8<=-0.5,ABS(K8)<0.5), "Beware of myopic shift for distance in bright light / small pupil conditions", IF(AND(J8>=0.5,ABS(K8)<0.5), "Possible hyperopic shift for distance in bright light / small pupil conditions", IF(AND(ABS(J8)<0.5,K8<=-0.5), "Chances of low-light myopia / night myopia likely", IF(AND(ABS(J8)<0.5,K8>=0.5), "Possible hyperopic shift in dim light / larger pupil conditions", IF(AND(J8<=-0.5,K8<=-0.5), "Consistent myopic shift tendency across lighting conditions", IF(AND(J8>=0.5,K8>=0.5), "Consistent hyperopic shift tendency across lighting conditions", IF(AND(J8<=-0.5,K8>=0.5), "Lighting-dependent refractive behavior likely, with myopic tendency in bright light and hyperopic tendency in dim light", IF(AND(J8>=0.5,K8<=-0.5), "Lighting-dependent refractive behavior likely, with hyperopic tendency in bright light and night myopia in dim light", "No clinically significant pupil-dependent refractive shift expected"))))))))) -> No clinically significant pupil-dependent refractive shift expected
B9: GEMETRIC | J9: =IF(OR(B9=$B$2,B9=$B$3,B9=$B$4,B9=$B$8,B9=$B$9,B9=$B$10),0, IF(B9=$B$5,INDEX($R$4:$T$7,MATCH(IF($D$2<2.5,2,IF($D$2<3.5,3,IF($D$2<4.5,4,5))),$O$4:$O$7,0),MATCH(IF($H$2<=0,"0 AND LESS",IF($H$2<0.4,"0.1 TO 0.3","0.4 AND ABOVE")),$R$3:$T$3,0)), IF(B9=$B$6,INDEX($R$11:$T$14,MATCH(IF($D$2<2.5,2,IF($D$2<3.5,3,IF($D$2<4.5,4,5))),$O$11:$O$14,0),MATCH(IF($H$2<=0,"0 AND LESS",IF($H$2<0.4,"0.1 TO 0.3","0.4 AND ABOVE")),$R$10:$T$10,0)), IF(B9=$B$7,INDEX($R$18:$T$21,MATCH(IF($D$2<2.5,2,IF($D$2<3.5,3,IF($D$2<4.5,4,5))),$O$18:$O$21,0),MATCH(IF($H$2<=0,"0 AND LESS",IF($H$2<0.4,"0.1 TO 0.3","0.4 AND ABOVE")),$R$17:$T$17,0)),0)))) -> 0 | K9: =IF(OR(B9=$B$2,B9=$B$3,B9=$B$4,B9=$B$8,B9=$B$9,B9=$B$10),0, IF(B9=$B$5,INDEX($R$4:$T$7,MATCH(IF($E$2<2.5,2,IF($E$2<3.5,3,IF($E$2<4.5,4,5))),$O$4:$O$7,0),MATCH(IF($H$2<=0,"0 AND LESS",IF($H$2<0.4,"0.1 TO 0.3","0.4 AND ABOVE")),$R$3:$T$3,0)), IF(B9=$B$6,INDEX($R$11:$T$14,MATCH(IF($E$2<2.5,2,IF($E$2<3.5,3,IF($E$2<4.5,4,5))),$O$11:$O$14,0),MATCH(IF($H$2<=0,"0 AND LESS",IF($H$2<0.4,"0.1 TO 0.3","0.4 AND ABOVE")),$R$10:$T$10,0)), IF(B9=$B$7,INDEX($R$18:$T$21,MATCH(IF($E$2<2.5,2,IF($E$2<3.5,3,IF($E$2<4.5,4,5))),$O$18:$O$21,0),MATCH(IF($H$2<=0,"0 AND LESS",IF($H$2<0.4,"0.1 TO 0.3","0.4 AND ABOVE")),$R$17:$T$17,0)),0)))) -> 0 | L9: =IF(AND(ABS(J9)<0.5,ABS(K9)<0.5), "No clinically significant pupil-dependent refractive shift expected", IF(AND(J9<=-0.5,ABS(K9)<0.5), "Beware of myopic shift for distance in bright light / small pupil conditions", IF(AND(J9>=0.5,ABS(K9)<0.5), "Possible hyperopic shift for distance in bright light / small pupil conditions", IF(AND(ABS(J9)<0.5,K9<=-0.5), "Chances of low-light myopia / night myopia likely", IF(AND(ABS(J9)<0.5,K9>=0.5), "Possible hyperopic shift in dim light / larger pupil conditions", IF(AND(J9<=-0.5,K9<=-0.5), "Consistent myopic shift tendency across lighting conditions", IF(AND(J9>=0.5,K9>=0.5), "Consistent hyperopic shift tendency across lighting conditions", IF(AND(J9<=-0.5,K9>=0.5), "Lighting-dependent refractive behavior likely, with myopic tendency in bright light and hyperopic tendency in dim light", IF(AND(J9>=0.5,K9<=-0.5), "Lighting-dependent refractive behavior likely, with hyperopic tendency in bright light and night myopia in dim light", "No clinically significant pupil-dependent refractive shift expected"))))))))) -> No clinically significant pupil-dependent refractive shift expected | N9: EMV | R9: CORNEAL SA
B10: ATLISA TRI | J10: =IF(OR(B10=$B$2,B10=$B$3,B10=$B$4,B10=$B$8,B10=$B$9,B10=$B$10),0, IF(B10=$B$5,INDEX($R$4:$T$7,MATCH(IF($D$2<2.5,2,IF($D$2<3.5,3,IF($D$2<4.5,4,5))),$O$4:$O$7,0),MATCH(IF($H$2<=0,"0 AND LESS",IF($H$2<0.4,"0.1 TO 0.3","0.4 AND ABOVE")),$R$3:$T$3,0)), IF(B10=$B$6,INDEX($R$11:$T$14,MATCH(IF($D$2<2.5,2,IF($D$2<3.5,3,IF($D$2<4.5,4,5))),$O$11:$O$14,0),MATCH(IF($H$2<=0,"0 AND LESS",IF($H$2<0.4,"0.1 TO 0.3","0.4 AND ABOVE")),$R$10:$T$10,0)), IF(B10=$B$7,INDEX($R$18:$T$21,MATCH(IF($D$2<2.5,2,IF($D$2<3.5,3,IF($D$2<4.5,4,5))),$O$18:$O$21,0),MATCH(IF($H$2<=0,"0 AND LESS",IF($H$2<0.4,"0.1 TO 0.3","0.4 AND ABOVE")),$R$17:$T$17,0)),0)))) -> 0 | K10: =IF(OR(B10=$B$2,B10=$B$3,B10=$B$4,B10=$B$8,B10=$B$9,B10=$B$10),0, IF(B10=$B$5,INDEX($R$4:$T$7,MATCH(IF($E$2<2.5,2,IF($E$2<3.5,3,IF($E$2<4.5,4,5))),$O$4:$O$7,0),MATCH(IF($H$2<=0,"0 AND LESS",IF($H$2<0.4,"0.1 TO 0.3","0.4 AND ABOVE")),$R$3:$T$3,0)), IF(B10=$B$6,INDEX($R$11:$T$14,MATCH(IF($E$2<2.5,2,IF($E$2<3.5,3,IF($E$2<4.5,4,5))),$O$11:$O$14,0),MATCH(IF($H$2<=0,"0 AND LESS",IF($H$2<0.4,"0.1 TO 0.3","0.4 AND ABOVE")),$R$10:$T$10,0)), IF(B10=$B$7,INDEX($R$18:$T$21,MATCH(IF($E$2<2.5,2,IF($E$2<3.5,3,IF($E$2<4.5,4,5))),$O$18:$O$21,0),MATCH(IF($H$2<=0,"0 AND LESS",IF($H$2<0.4,"0.1 TO 0.3","0.4 AND ABOVE")),$R$17:$T$17,0)),0)))) -> 0 | L10: =IF(AND(ABS(J10)<0.5,ABS(K10)<0.5), "No clinically significant pupil-dependent refractive shift expected", IF(AND(J10<=-0.5,ABS(K10)<0.5), "Beware of myopic shift for distance in bright light / small pupil conditions", IF(AND(J10>=0.5,ABS(K10)<0.5), "Possible hyperopic shift for distance in bright light / small pupil conditions", IF(AND(ABS(J10)<0.5,K10<=-0.5), "Chances of low-light myopia / night myopia likely", IF(AND(ABS(J10)<0.5,K10>=0.5), "Possible hyperopic shift in dim light / larger pupil conditions", IF(AND(J10<=-0.5,K10<=-0.5), "Consistent myopic shift tendency across lighting conditions", IF(AND(J10>=0.5,K10>=0.5), "Consistent hyperopic shift tendency across lighting conditions", IF(AND(J10<=-0.5,K10>=0.5), "Lighting-dependent refractive behavior likely, with myopic tendency in bright light and hyperopic tendency in dim light", IF(AND(J10>=0.5,K10<=-0.5), "Lighting-dependent refractive behavior likely, with hyperopic tendency in bright light and night myopia in dim light", "No clinically significant pupil-dependent refractive shift expected"))))))))) -> No clinically significant pupil-dependent refractive shift expected | O10: PUPIL SIZE | P10: REFRACTIVE EFFECT | R10: 0 AND LESS | S10: 0.1 TO 0.3 | T10: 0.4 AND ABOVE
O11: 2 | R11: 0.5 | S11: 0.5 | T11: 0.5
O12: 3 | R12: 0.25 | S12: 0 | T12: 0
O13: 4 | R13: 0 | S13: 0 | T13: 0
O14: 5 | R14: 0 | S14: 0 | T14: 0
N16: VIVITY | R16: CORNEAL SA
O17: PUPIL SIZE | P17: REFRACTIVE EFFECT | R17: 0 AND LESS | S17: 0.1 TO 0.3 | T17: 0.4 AND ABOVE
O18: 2 | R18: 0 | S18: 0 | T18: 0
O19: 3 | R19: 0 | S19: -0.25 | T19: -0.5
O20: 4 | R20: 0 | S20: -0.37 | T20: -0.75
O21: 5 | S21: -0.37 | T21: -0.75

Sheet PANOPTIX
A1: DOF | C1: CORNEAL SA 6MM | D1: -0.5 | E1: -0.4 | F1: -0.3 | G1: -0.2 | H1: -0.1 | I1: 0 | J1: 0.1 | K1: 0.2 | L1: 0.3 | M1: 0.4 | N1: 0.5 | O1: 0.6 | P1: 1 | R1: Spherical IOL Lookup
B2: PHOTOPIC PUPIL
B3: =3 -> 3 | D3: 2.9 | E3: 2.9 | F3: 3 | G3: 3 | H3: 3 | I3: 3 | J3: 3 | K3: 3 | L3: 3 | M3: 3 | N3: 3 | O3: 3 | P3: 3 | R3: User inputs
B4: 4.5 | D4: 1 | E4: 1 | F4: 1 | G4: 1 | H4: 1.1 | I4: 1 | J4: 1 | K4: 1 | L4: 1 | M4: 1 | N4: 1 | O4: 1 | P4: 1 | R4: Corneal SA 6 mm | S4: ='INPUT DATA'!G2 -> 0.35 | V4: CORNEAL VC 6mm | W4: ='INPUT DATA'!H2 -> 0.06
R5: Photopic pupil (mm) | S5: ='INPUT DATA'!C2 -> 1.8 | V5: CORNEAL HC 6mm | W5: ='INPUT DATA'!I2 -> 0.05
B6: R DOF | D6: =D4/D3 -> 0.34482759 | E6: =E4/E3 -> 0.34482759 | F6: =F4/F3 -> 0.33333333 | G6: =G4/G3 -> 0.33333333 | H6: =H4/H3 -> 0.36666667 | I6: =I4/I3 -> 0.33333333 | J6: =J4/J3 -> 0.33333333 | K6: =K4/K3 -> 0.33333333 | ... P6: =P4/P3 -> 0.33333333 | R6: Scotopic pupil (mm) | S6: ='INPUT DATA'!D2 -> 3.5
R9: DOF PUPIL FACTOR | S9: =IF(S5<=3,MAX(0.55,1-0.18*(3-S5)^2), IF(S5<=4,1-0.12*(S5-3)^2, IF(S5<=4.5,0.88-(0.88-INDEX(D6:P6,MATCH(ROUND(S4,1),D1:P1,0)))*(S5-4)/0.5, MAX(0.18,INDEX(D6:P6,MATCH(ROUND(S4,1),D1:P1,0))-0.1*(S5-4.5))))) -> 0.7408
A10: MTFa MAX | C10: CORNEAL SA 6MM | D10: -0.5 | E10: -0.4 | F10: -0.3 | G10: -0.2 | H10: -0.1 | I10: 0 | J10: 0.1 | K10: 0.2 | L10: 0.3 | M10: 0.4 | N10: 0.5 | O10: 0.6 | P10: 1 | R10: MTF PUPIL FACTOR | S10: =IF(S6<=3,MAX(0.75,1-0.08*(3-S6)^2), IF(S6<=4,1-0.05*(S6-3)^2, IF(S6<=4.5,0.95-(0.95-INDEX(D15:P15,MATCH(ROUND(S4,1),D10:P10,0)))*(S6-4)/0.5, MAX(0.6,INDEX(D15:P15,MATCH(ROUND(S4,1),D10:P10,0))-0.07*(S6-4.5))))) -> 0.9875
B11: SCOTOPIC PUPIL
B12: 3 | D12: 4.8 | E12: 5 | F12: 5.1 | G12: 5.3 | H12: 5.5 | I12: 5.5 | J12: 5.7 | K12: 5.7 | L12: 5.8 | M12: 5.8 | N12: 5.8 | O12: 5.8 | P12: 5.8 | R12: DOF | S12: =INDEX(D3:P3,1,MATCH(ROUND(S4,1),D1:P1,0))*S9 -> 2.2224
B13: 4.5 | D13: 3 | E13: 3.1 | F13: 3.3 | G13: 3.6 | H13: 3.8 | I13: 4.2 | J13: 4.6 | K13: 5 | L13: 4.5 | M13: 3.5 | N13: 3.5 | O13: 3 | P13: 2.5 | R13: MTF | S13: =INDEX(D12:P12,1,MATCH(ROUND(S4,1),D10:P10,0))*S10 -> 5.7275 | V13: DOF AFTER COMA | W13: =ROUND(MAX(0,S12-MIN(0.5,1.2*SQRT((W4)^2+(0.7*W5)^2)*(S5/6)^2)),1) -> 2.2
V14: DOF AFTER ANGLES | W14: =ROUND(MAX(0,W13*MAX(0.95,1-0.06*MAX(0,S23-0.3)-0.03*MAX(0,S24-0.3))),1) -> 2.2
B15: R MTF | D15: =D13/D12 -> 0.625 | E15: =E13/E12 -> 0.62 | F15: =F13/F12 -> 0.64705882 | G15: =G13/G12 -> 0.67924528 | H15: =H13/H12 -> 0.69090909 | I15: =I13/I12 -> 0.76363636 | J15: =J13/J12 -> 0.80701754 | K15: =K13/K12 -> 0.87719298 | ... P15: =P13/P12 -> 0.43103448
V16: MTF AFTER COMA | W16: =ROUND(MAX(0,S13-MIN(3,5.8*SQRT((W4)^2+(0.7*W5)^2)*(S6/6)^3)),1) -> 5.6
V17: MTF AFTER ANGLES | W17: =ROUND(MAX(0,W16*MAX(0.85,1-0.3*MAX(0,S23-0.3)-0.2*MAX(0,S24-0.3))),1) -> 5.6
V20: DOF GRADING
V21: =IF(W48<0.75,"Distance only / No functional near", IF(W48<1.25,"Weak intermediate, poor near", IF(W48<1.75,"Functional intermediate, limited near", IF(W48<2.25,"Good intermediate and near", "Excellent near performance")))) -> Good intermediate and near
R23: ANGLE ALPHA | S23: ='INPUT DATA'!E2 -> 0.1 | V23: PREDICTED VISUAL QUALITY SCORE
R24: ANGLE KAPPA | S24: ='INPUT DATA'!F2 -> 0.25 | V24: =ROUND(IF(W17>=6,10,IF(W17>=4,7+((W17-4)/2)*3,IF(W17>=3,5+((W17-3)/1)*2,IF(W17>=2,3+((W17-2)/1)*2,MAX(0,(W17/2)*3))))),1) -> 9.4
V26: PREDICTED VISUAL QUALITY GRADE
V27: =IF(W47>=6,"excellent visual quality across all lighting conditions",IF(W47>=5,"Excellent visual quality in normal lighting; mild reduction may be noticed in very low-light conditions",IF(W47>=4,"Very good visual quality in bright lighting; noticeable decline in low-light environments",IF(W47>=3,"Functional visual quality in good lighting; significant deterioration expected in dim light",IF(W47>=2,"Suboptimal visual quality even in bright conditions; poor performance in low light","Poor overall visual quality across all lighting conditions"))))) -> Very good visual quality in bright lighting; noticeable decline in low-light environments
V28: NEAR VISION SCORE
V29: =ROUND(MIN(10,W14*3.4),1) -> 7.5
V31: dysphotopsia
V32: ='DYSPHOTOPSIA SCORES'!E27 -> 5.5
V38: pathology | W38: grade
V39: ='INPUT DATA'!J2 -> CORNEAL ENDOTHELIAL DISEASE | W39: ='INPUT DATA'!K2 -> 1
V40: ='INPUT DATA'!J3 -> DRY EYE DISEASE | W40: ='INPUT DATA'!K3 -> 1
V41: ='INPUT DATA'!J4 -> 0 | W41: ='INPUT DATA'!K4 -> 0
V42: ='INPUT DATA'!J5 -> 0 | W42: ='INPUT DATA'!K5 -> 0
V43: ='INPUT DATA'!J6 -> 0 | W43: ='INPUT DATA'!K6 -> 0
V47: PATHOLOGY ADJUSTED MTF | W47: =ROUND(W17*(1-(1-( CHOOSE(IFERROR(INDEX($W$39:$W$43,MATCH("DRY EYE DISEASE",$V$39:$V$43,0)),0)+1,1,0.95,0.85,0.7)* CHOOSE(IFERROR(INDEX($W$39:$W$43,MATCH("MACULAR PATHOLOGY",$V$39:$V$43,0)),0)+1,1,0.9,0.75,0.55)* CHOOSE(IFERROR(INDEX($W$39:$W$43,MATCH("DIABETIC RETINOPATHY",$V$39:$V$43,0)),0)+1,1,0.92,0.8,0.6)* CHOOSE(IFERROR(INDEX($W$39:$W$43,MATCH("GLAUCOMA",$V$39:$V$43,0)),0)+1,1,0.93,0.82,0.65)* CHOOSE(IFERROR(INDEX($W$39:$W$43,MATCH("CORNEAL ENDOTHELIAL DISEASE",$V$39:$V$43,0)),0)+1,1,0.9,0.72,0.5) ))*1.3),1) -> 4.5
V48: PATHOLOGY ADJUSTED DOF | W48: =ROUND(W14*(1-(1-( CHOOSE(IFERROR(INDEX($W$39:$W$43,MATCH("DRY EYE DISEASE",$V$39:$V$43,0)),0)+1,1,0.97,0.9,0.75)* CHOOSE(IFERROR(INDEX($W$39:$W$43,MATCH("MACULAR PATHOLOGY",$V$39:$V$43,0)),0)+1,1,0.92,0.8,0.6)* CHOOSE(IFERROR(INDEX($W$39:$W$43,MATCH("DIABETIC RETINOPATHY",$V$39:$V$43,0)),0)+1,1,0.94,0.85,0.68)* CHOOSE(IFERROR(INDEX($W$39:$W$43,MATCH("GLAUCOMA",$V$39:$V$43,0)),0)+1,1,0.95,0.86,0.7)* CHOOSE(IFERROR(INDEX($W$39:$W$43,MATCH("CORNEAL ENDOTHELIAL DISEASE",$V$39:$V$43,0)),0)+1,1,0.94,0.82,0.6) ))*1.3),2) -> 1.95

Sheet GEMETRIC
A1: DOF | C1: CORNEAL SA 6MM | D1: -0.5 | E1: -0.4 | F1: -0.3 | G1: -0.2 | H1: -0.1 | I1: 0 | J1: 0.1 | K1: 0.2 | L1: 0.3 | M1: 0.4 | N1: 0.5 | O1: 0.6 | P1: 1 | R1: Spherical IOL Lookup
B2: PHOTOPIC PUPIL
B3: =3 -> 3 | D3: 2.5 | E3: 2.4 | F3: 2.3 | G3: 2.3 | H3: 2.3 | I3: 2.3 | J3: 2.3 | K3: 2.3 | L3: 2.3 | M3: 2.3 | N3: 2.3 | O3: 2.3 | P3: 2.4 | R3: User inputs
B4: 4.5 | D4: 1 | E4: 1 | F4: 1 | G4: 1 | H4: 1 | I4: 1 | J4: 1 | K4: 1 | L4: 1 | M4: 1 | N4: 1 | O4: 1 | P4: 1 | R4: Corneal SA 6 mm | S4: ='INPUT DATA'!G2 -> 0.35 | V4: CORNEAL VC 6mm | W4: ='INPUT DATA'!H2 -> 0.06
R5: Photopic pupil (mm) | S5: ='INPUT DATA'!C2 -> 1.8 | V5: CORNEAL HC 6mm | W5: ='INPUT DATA'!I2 -> 0.05
B6: R DOF | D6: =D4/D3 -> 0.4 | E6: =E4/E3 -> 0.41666667 | F6: =F4/F3 -> 0.43478261 | G6: =G4/G3 -> 0.43478261 | H6: =H4/H3 -> 0.43478261 | I6: =I4/I3 -> 0.43478261 | J6: =J4/J3 -> 0.43478261 | K6: =K4/K3 -> 0.43478261 | ... P6: =P4/P3 -> 0.41666667 | R6: Scotopic pupil (mm) | S6: ='INPUT DATA'!D2 -> 3.5
R9: DOF PUPIL FACTOR | S9: =IF(S5<=3,MAX(0.6,1-0.15*(3-S5)^2), IF(S5<=4,1-0.1*(S5-3)^2, IF(S5<=4.5,0.9-(0.9-INDEX(D6:P6,MATCH(ROUND(S4,1),D1:P1,0)))*(S5-4)/0.5, MAX(0.22,INDEX(D6:P6,MATCH(ROUND(S4,1),D1:P1,0))-0.08*(S5-4.5))))) -> 0.784
A10: MTFa MAX | C10: CORNEAL SA 6MM | D10: -0.5 | E10: -0.4 | F10: -0.3 | G10: -0.2 | H10: -0.1 | I10: 0 | J10: 0.1 | K10: 0.2 | L10: 0.3 | M10: 0.4 | N10: 0.5 | O10: 0.6 | P10: 1 | R10: MTF PUPIL FACTOR | S10: =IF(S6<=3,MAX(0.8,1-0.06*(3-S6)^2), IF(S6<=4,1-0.035*(S6-3)^2, IF(S6<=4.5,0.96-(0.96-INDEX(D15:P15,MATCH(ROUND(S4,1),D10:P10,0)))*(S6-4)/0.5, MAX(0.68,INDEX(D15:P15,MATCH(ROUND(S4,1),D10:P10,0))-0.05*(S6-4.5))))) -> 0.99125
B11: SCOTOPIC PUPIL
B12: 3 | D12: 4.7 | E12: 4.8 | F12: 4.9 | G12: 5.1 | H12: 5.2 | I12: 5.2 | J12: 5.3 | K12: 5.4 | L12: 5.4 | M12: 5.4 | N12: 5.4 | O12: 5.4 | P12: 5.4 | R12: DOF | S12: =INDEX(D3:P3,1,MATCH(ROUND(S4,1),D1:P1,0))*S9 -> 1.8032
B13: 4.5 | D13: 3.5 | E13: 3.7 | F13: 3.9 | G13: 4.2 | H13: 4.5 | I13: 4.9 | J13: 5.1 | K13: 5.1 | L13: 5 | M13: 4.5 | N13: 4 | O13: 3.5 | P13: 3 | R13: MTF | S13: =INDEX(D12:P12,1,MATCH(ROUND(S4,1),D10:P10,0))*S10 -> 5.35275 | V13: DOF AFTER COMA | W13: =ROUND(MAX(0,S12-MIN(0.4,1*SQRT((W4)^2+(0.7*W5)^2)*(S5/6)^2)),1) -> 1.8
V14: DOF AFTER ANGLES | W14: =ROUND(MAX(0,W13*MAX(0.96,1-0.05*MAX(0,S23-0.3)-0.025*MAX(0,S24-0.3))),1) -> 1.8
B15: R MTF | D15: =D13/D12 -> 0.74468085 | E15: =E13/E12 -> 0.77083333 | F15: =F13/F12 -> 0.79591837 | G15: =G13/G12 -> 0.82352941 | H15: =H13/H12 -> 0.86538462 | I15: =I13/I12 -> 0.94230769 | J15: =J13/J12 -> 0.96226415 | K15: =K13/K12 -> 0.94444444 | ... P15: =P13/P12 -> 0.55555556
V16: MTF AFTER COMA | W16: =ROUND(MAX(0,S13-MIN(2.7,5*SQRT((W4)^2+(0.7*W5)^2)*(S6/6)^3)),1) -> 5.3
V17: MTF AFTER ANGLES | W17: =ROUND(MAX(0,W16*MAX(0.88,1-0.25*MAX(0,S23-0.3)-0.15*MAX(0,S24-0.3))),1) -> 5.3
V20: DOF GRADING
V21: =IF(W48<0.75,"Distance only / No functional near", IF(W48<1.25,"Weak intermediate, poor near", IF(W48<1.75,"Functional intermediate, limited near", IF(W48<2.25,"Good intermediate and near", "Excellent near performance")))) -> Functional intermediate, limited near
R23: ANGLE ALPHA | S23: ='INPUT DATA'!E2 -> 0.1 | V23: PREDICTED VISUAL QUALITY SCORE
R24: ANGLE KAPPA | S24: ='INPUT DATA'!F2 -> 0.25 | V24: =ROUND(IF(W17>=6,10,IF(W17>=4,7+((W17-4)/2)*3,IF(W17>=3,5+((W17-3)/1)*2,IF(W17>=2,3+((W17-2)/1)*2,MAX(0,(W17/2)*3))))),1) -> 9
V26: PREDICTED VISUAL QUALITY GRADE
V27: =IF(W47>=6,"excellent visual quality across all lighting conditions",IF(W47>=5,"Excellent visual quality in normal lighting; mild reduction may be noticed in very low-light conditions",IF(W47>=4,"Very good visual quality in bright lighting; noticeable decline in low-light environments",IF(W47>=3,"Functional visual quality in good lighting; significant deterioration expected in dim light",IF(W47>=2,"Suboptimal visual quality even in bright conditions; poor performance in low light","Poor overall visual quality across all lighting conditions"))))) -> Very good visual quality in bright lighting; noticeable decline in low-light environments
V28: NEAR VISION SCORE
V29: =ROUND(MIN(10,W14*3.4),1) -> 6.1
V31: dysphotopsia
V32: ='DYSPHOTOPSIA SCORES'!E25 -> 4.9
V38: pathology | W38: grade
V39: ='INPUT DATA'!J2 -> CORNEAL ENDOTHELIAL DISEASE | W39: ='INPUT DATA'!K2 -> 1
V40: ='INPUT DATA'!J3 -> DRY EYE DISEASE | W40: ='INPUT DATA'!K3 -> 1
V41: ='INPUT DATA'!J4 -> 0 | W41: ='INPUT DATA'!K4 -> 0
V42: ='INPUT DATA'!J5 -> 0 | W42: ='INPUT DATA'!K5 -> 0
V43: ='INPUT DATA'!J6 -> 0 | W43: ='INPUT DATA'!K6 -> 0
V47: PATHOLOGY ADJUSTED MTF | W47: =ROUND(W17*(1-(1-( CHOOSE(IFERROR(INDEX($W$39:$W$43,MATCH("DRY EYE DISEASE",$V$39:$V$43,0)),0)+1,1,0.95,0.85,0.7)* CHOOSE(IFERROR(INDEX($W$39:$W$43,MATCH("MACULAR PATHOLOGY",$V$39:$V$43,0)),0)+1,1,0.9,0.75,0.55)* CHOOSE(IFERROR(INDEX($W$39:$W$43,MATCH("DIABETIC RETINOPATHY",$V$39:$V$43,0)),0)+1,1,0.92,0.8,0.6)* CHOOSE(IFERROR(INDEX($W$39:$W$43,MATCH("GLAUCOMA",$V$39:$V$43,0)),0)+1,1,0.93,0.82,0.65)* CHOOSE(IFERROR(INDEX($W$39:$W$43,MATCH("CORNEAL ENDOTHELIAL DISEASE",$V$39:$V$43,0)),0)+1,1,0.9,0.72,0.5) ))*1.2),1) -> 4.4
V48: PATHOLOGY ADJUSTED DOF | W48: =ROUND(W14*(1-(1-( CHOOSE(IFERROR(INDEX($W$39:$W$43,MATCH("DRY EYE DISEASE",$V$39:$V$43,0)),0)+1,1,0.97,0.9,0.75)* CHOOSE(IFERROR(INDEX($W$39:$W$43,MATCH("MACULAR PATHOLOGY",$V$39:$V$43,0)),0)+1,1,0.92,0.8,0.6)* CHOOSE(IFERROR(INDEX($W$39:$W$43,MATCH("DIABETIC RETINOPATHY",$V$39:$V$43,0)),0)+1,1,0.94,0.85,0.68)* CHOOSE(IFERROR(INDEX($W$39:$W$43,MATCH("GLAUCOMA",$V$39:$V$43,0)),0)+1,1,0.95,0.86,0.7)* CHOOSE(IFERROR(INDEX($W$39:$W$43,MATCH("CORNEAL ENDOTHELIAL DISEASE",$V$39:$V$43,0)),0)+1,1,0.94,0.82,0.6) ))*1.2),2) -> 1.61

Sheet ATLISA TRI
A1: DOF | C1: CORNEAL SA 6MM | D1: -0.5 | E1: -0.4 | F1: -0.3 | G1: -0.2 | H1: -0.1 | I1: 0 | J1: 0.1 | K1: 0.2 | L1: 0.3 | M1: 0.4 | N1: 0.5 | O1: 0.6 | P1: 1 | R1: Spherical IOL Lookup
B2: PHOTOPIC PUPIL
B3: =3 -> 3 | D3: 2.6 | E3: 2.6 | F3: 2.6 | G3: 2.6 | H3: 2.6 | I3: 2.6 | J3: 2.5 | K3: 2.5 | L3: 2.5 | M3: 2.5 | N3: 2.5 | O3: 2.5 | P3: 2.6 | R3: User inputs
B4: 4.5 | D4: 1.2 | E4: 1.2 | F4: 1.2 | G4: 1.1 | H4: 1.1 | I4: 1.1 | J4: 1.1 | K4: 1.1 | L4: 1 | M4: 1 | N4: 1 | O4: 1 | P4: 1 | R4: Corneal SA 6 mm | S4: ='INPUT DATA'!G2 -> 0.35 | V4: CORNEAL VC 6mm | W4: ='INPUT DATA'!H2 -> 0.06
R5: Photopic pupil (mm) | S5: ='INPUT DATA'!C2 -> 1.8 | V5: CORNEAL HC 6mm | W5: ='INPUT DATA'!I2 -> 0.05
B6: R DOF | D6: =D4/D3 -> 0.46153846 | E6: =E4/E3 -> 0.46153846 | F6: =F4/F3 -> 0.46153846 | G6: =G4/G3 -> 0.42307692 | H6: =H4/H3 -> 0.42307692 | I6: =I4/I3 -> 0.42307692 | J6: =J4/J3 -> 0.44 | K6: =K4/K3 -> 0.44 | ... P6: =P4/P3 -> 0.38461538 | R6: Scotopic pupil (mm) | S6: ='INPUT DATA'!D2 -> 3.5
R9: DOF PUPIL FACTOR | S9: =IF(S5<=3,MAX(0.58,1-0.16*(3-S5)^2), IF(S5<=4,1-0.11*(S5-3)^2, IF(S5<=4.5,0.89-(0.89-INDEX(D6:P6,MATCH(ROUND(S4,1),D1:P1,0)))*(S5-4)/0.5, MAX(0.2,INDEX(D6:P6,MATCH(ROUND(S4,1),D1:P1,0))-0.09*(S5-4.5))))) -> 0.7696
A10: MTFa MAX | C10: CORNEAL SA 6MM | D10: -0.5 | E10: -0.4 | F10: -0.3 | G10: -0.2 | H10: -0.1 | I10: 0 | J10: 0.1 | K10: 0.2 | L10: 0.3 | M10: 0.4 | N10: 0.5 | O10: 0.6 | P10: 1 | R10: MTF PUPIL FACTOR | S10: =IF(S6<=3,MAX(0.78,1-0.07*(3-S6)^2), IF(S6<=4,1-0.04*(S6-3)^2, IF(S6<=4.5,0.955-(0.955-INDEX(D15:P15,MATCH(ROUND(S4,1),D10:P10,0)))*(S6-4)/0.5, MAX(0.64,INDEX(D15:P15,MATCH(ROUND(S4,1),D10:P10,0))-0.06*(S6-4.5))))) -> 0.99
B11: SCOTOPIC PUPIL
B12: 3 | D12: 4.7 | E12: 4.9 | F12: 5.1 | G12: 5.3 | H12: 5.5 | I12: 5.6 | J12: 5.7 | K12: 5.8 | L12: 5.8 | M12: 5.8 | N12: 5.8 | O12: 5.8 | P12: 5.8 | R12: DOF | S12: =INDEX(D3:P3,1,MATCH(ROUND(S4,1),D1:P1,0))*S9 -> 1.924
B13: 4.5 | D13: 2 | E13: 2.5 | F13: 2.5 | G13: 3.5 | H13: 3.5 | I13: 4.3 | J13: 4.7 | K13: 5.1 | L13: 5.4 | M13: 3.5 | N13: 3.5 | O13: 3 | P13: 2.5 | R13: MTF | S13: =INDEX(D12:P12,1,MATCH(ROUND(S4,1),D10:P10,0))*S10 -> 5.742 | V13: DOF AFTER COMA | W13: =ROUND(MAX(0,S12-MIN(0.48,1.15*SQRT((W4)^2+(0.7*W5)^2)*(S5/6)^2)),1) -> 1.9
V14: DOF AFTER ANGLES | W14: =ROUND(MAX(0,W13*MAX(0.95,1-0.058*MAX(0,S23-0.3)-0.03*MAX(0,S24-0.3))),1) -> 1.9
B15: R MTF | D15: =D13/D12 -> 0.42553191 | E15: =E13/E12 -> 0.51020408 | F15: =F13/F12 -> 0.49019608 | G15: =G13/G12 -> 0.66037736 | H15: =H13/H12 -> 0.63636364 | I15: =I13/I12 -> 0.76785714 | J15: =J13/J12 -> 0.8245614 | K15: =K13/K12 -> 0.87931034 | ... P15: =P13/P12 -> 0.43103448
V16: MTF AFTER COMA | W16: =ROUND(MAX(0,S13-MIN(3,5.6*SQRT((W4)^2+(0.7*W5)^2)*(S6/6)^3)),1) -> 5.7
V17: MTF AFTER ANGLES | W17: =ROUND(MAX(0,W16*MAX(0.85,1-0.29*MAX(0,S23-0.3)-0.19*MAX(0,S24-0.3))),1) -> 5.7
V20: DOF GRADING
V21: =IF(W48<0.75,"Distance only / No functional near", IF(W48<1.25,"Weak intermediate, poor near", IF(W48<1.75,"Functional intermediate, limited near", IF(W48<2.25,"Good intermediate and near", "Excellent near performance")))) -> Functional intermediate, limited near
R23: ANGLE ALPHA | S23: ='INPUT DATA'!E2 -> 0.1 | V23: PREDICTED VISUAL QUALITY SCORE
R24: ANGLE KAPPA | S24: ='INPUT DATA'!F2 -> 0.25 | V24: =ROUND(IF(W17>=6,10,IF(W17>=4,7+((W17-4)/2)*3,IF(W17>=3,5+((W17-3)/1)*2,IF(W17>=2,3+((W17-2)/1)*2,MAX(0,(W17/2)*3))))),1) -> 9.6
V26: PREDICTED VISUAL QUALITY GRADE
V27: =IF(W47>=6,"excellent visual quality across all lighting conditions",IF(W47>=5,"Excellent visual quality in normal lighting; mild reduction may be noticed in very low-light conditions",IF(W47>=4,"Very good visual quality in bright lighting; noticeable decline in low-light environments",IF(W47>=3,"Functional visual quality in good lighting; significant deterioration expected in dim light",IF(W47>=2,"Suboptimal visual quality even in bright conditions; poor performance in low light","Poor overall visual quality across all lighting conditions"))))) -> Very good visual quality in bright lighting; noticeable decline in low-light environments
V28: NEAR VISION SCORE
V29: =ROUND(MIN(10,W14*3.4),1) -> 6.5
V31: dysphotopsia
V32: ='DYSPHOTOPSIA SCORES'!E26 -> 5.3
V38: pathology | W38: grade
V39: ='INPUT DATA'!J2 -> CORNEAL ENDOTHELIAL DISEASE | W39: ='INPUT DATA'!K2 -> 1
V40: ='INPUT DATA'!J3 -> DRY EYE DISEASE | W40: ='INPUT DATA'!K3 -> 1
V41: ='INPUT DATA'!J4 -> 0 | W41: ='INPUT DATA'!K4 -> 0
V42: ='INPUT DATA'!J5 -> 0 | W42: ='INPUT DATA'!K5 -> 0
V43: ='INPUT DATA'!J6 -> 0 | W43: ='INPUT DATA'!K6 -> 0
V47: PATHOLOGY ADJUSTED MTF | W47: =ROUND(W17*(1-(1-( CHOOSE(IFERROR(INDEX($W$39:$W$43,MATCH("DRY EYE DISEASE",$V$39:$V$43,0)),0)+1,1,0.95,0.85,0.7)* CHOOSE(IFERROR(INDEX($W$39:$W$43,MATCH("MACULAR PATHOLOGY",$V$39:$V$43,0)),0)+1,1,0.9,0.75,0.55)* CHOOSE(IFERROR(INDEX($W$39:$W$43,MATCH("DIABETIC RETINOPATHY",$V$39:$V$43,0)),0)+1,1,0.92,0.8,0.6)* CHOOSE(IFERROR(INDEX($W$39:$W$43,MATCH("GLAUCOMA",$V$39:$V$43,0)),0)+1,1,0.93,0.82,0.65)* CHOOSE(IFERROR(INDEX($W$39:$W$43,MATCH("CORNEAL ENDOTHELIAL DISEASE",$V$39:$V$43,0)),0)+1,1,0.9,0.72,0.5) ))*1.25),1) -> 4.7
V48: PATHOLOGY ADJUSTED DOF | W48: =ROUND(W14*(1-(1-( CHOOSE(IFERROR(INDEX($W$39:$W$43,MATCH("DRY EYE DISEASE",$V$39:$V$43,0)),0)+1,1,0.97,0.9,0.75)* CHOOSE(IFERROR(INDEX($W$39:$W$43,MATCH("MACULAR PATHOLOGY",$V$39:$V$43,0)),0)+1,1,0.92,0.8,0.6)* CHOOSE(IFERROR(INDEX($W$39:$W$43,MATCH("DIABETIC RETINOPATHY",$V$39:$V$43,0)),0)+1,1,0.94,0.85,0.68)* CHOOSE(IFERROR(INDEX($W$39:$W$43,MATCH("GLAUCOMA",$V$39:$V$43,0)),0)+1,1,0.95,0.86,0.7)* CHOOSE(IFERROR(INDEX($W$39:$W$43,MATCH("CORNEAL ENDOTHELIAL DISEASE",$V$39:$V$43,0)),0)+1,1,0.94,0.82,0.6) ))*1.25),2) -> 1.69

Sheet DYSPHOTOPSIA SCORES
A1: pupil size | C1: VC | D1: HC | E1: ALPHA | F1: KAPPA | G1: total HOA | H1: CORNEAL SA
A2: ='INPUT DATA'!D2 -> 3.5 | C2: ='INPUT DATA'!H2 -> 0.06 | D2: ='INPUT DATA'!I2 -> 0.05 | E2: ='INPUT DATA'!E2 -> 0.1 | F2: ='INPUT DATA'!F2 -> 0.25 | G2: =ROUND(SQRT((1.5*$H$2)^2+$C$2^2+$D$2^2),3) -> 0.531 | H2: ='INPUT DATA'!G2 -> 0.35
D4: <=3 | E4: 3.1-4.5 | F4: >4.5
C5: NEG ASP | D5: 1 | E5: 1.5 | F5: 2.3
C6: ZERO ASP | D6: 1.1 | E6: 1.6 | F6: 2.5
C7: SPH | D7: 1.3 | E7: 1.8 | F7: 2.8
C8: EMV | D8: 2 | E8: 2.5 | F8: 3.2
C9: EYHANCE | D9: 2.1 | E9: 2.6 | F9: 3.5
C10: VIVITY | D10: 3.2 | E10: 4 | F10: 5
C11: GEME | D11: 6 | E11: 7 | F11: 8
C12: ATLISA | D12: 6.4 | E12: 7.6 | F12: 8.8
C13: PANOP | D13: 6.8 | E13: 7.8 | F13: 9
C18: BASIC SCORE | D18: pupil modifier | E18: FINAL SCORE AFTER ANGLE PENALTY | F18: final score
B19: NEG ASP | C19: =IF(ABS($H$2-0.15)<=0.1,0,IF(ABS($H$2-0.15)<=0.25,0.4,IF(ABS($H$2-0.15)<=0.5,0.8,1.5))) -> 0.4 | D19: =(ROUND(MAX(0,(($A$2-3)^2)*0.08*C19),2))+C19 -> 0.41 | E19: =ROUND(MIN(10, D19 + ((0.6*$G$2)+(1.2*MAX(0,$E$2-0.2))+(0.6*MAX(0,$F$2-0.2))) * (0.5 + 0.05*D19) ),1) -> 0.6 | F19: =ROUND(MIN(10, E19+ ( 0.6*CHOOSE(IFERROR(INDEX($F$35:$F$39,MATCH("DRY EYE DISEASE",$E$35:$E$39,0)),0)+1,0,0.5,1.5,3)+ 0.5*CHOOSE(IFERROR(INDEX($F$35:$F$39,MATCH("MACULAR PATHOLOGY",$E$35:$E$39,0)),0)+1,0,0.3,0.8,1.5)+ 0.5*CHOOSE(IFERROR(INDEX($F$35:$F$39,MATCH("DIABETIC RETINOPATHY",$E$35:$E$39,0)),0)+1,0,0.2,0.5,1)+ 0.5*CHOOSE(IFERROR(INDEX($F$35:$F$39,MATCH("GLAUCOMA",$E$35:$E$39,0)),0)+1,0,0.2,0.5,1)+ 0.6*CHOOSE(IFERROR(INDEX($F$35:$F$39,MATCH("CORNEAL ENDOTHELIAL DISEASE",$E$35:$E$39,0)),0)+1,0,0.8,2,4)+ IF(AND( IFERROR(INDEX($F$35:$F$39,MATCH("DRY EYE DISEASE",$E$35:$E$39,0)),0)>=2, IFERROR(INDEX($F$35:$F$39,MATCH("CORNEAL ENDOTHELIAL DISEASE",$E$35:$E$39,0)),0)>=2 ),0.5,0) ) * IF(B19="NEG ASP",0.75, IF(B19="ZERO ASP",0.78, IF(B19="SPH",0.8, IF(B19="EMV",0.85, IF(B19="EYHANCE",0.9, IF(B19="VIVITY",1, IF(B19="GEME",1.1, IF(B19="ATLISA",1.15, IF(B19="PANOP",1.2,1))))))))) ),1) -> 1.2
B20: ZERO ASP | C20: =IF(ABS($H$2)<=0.1,0,IF(ABS($H$2)<=0.25,0.4,IF(ABS($H$2)<=0.5,0.8,1.5))) -> 0.8 | D20: =(ROUND(MAX(0,(($A$2-3)^2)*0.08*C20),2))+C20 -> 0.82 | E20: =ROUND(MIN(10, D20 + ((0.6*$G$2)+(1.2*MAX(0,$E$2-0.2))+(0.6*MAX(0,$F$2-0.2))) * (0.5 + 0.05*D20) ),1) -> 1 | F20: =ROUND(MIN(10, E20+ ( 0.6*CHOOSE(IFERROR(INDEX($F$35:$F$39,MATCH("DRY EYE DISEASE",$E$35:$E$39,0)),0)+1,0,0.5,1.5,3)+ 0.5*CHOOSE(IFERROR(INDEX($F$35:$F$39,MATCH("MACULAR PATHOLOGY",$E$35:$E$39,0)),0)+1,0,0.3,0.8,1.5)+ 0.5*CHOOSE(IFERROR(INDEX($F$35:$F$39,MATCH("DIABETIC RETINOPATHY",$E$35:$E$39,0)),0)+1,0,0.2,0.5,1)+ 0.5*CHOOSE(IFERROR(INDEX($F$35:$F$39,MATCH("GLAUCOMA",$E$35:$E$39,0)),0)+1,0,0.2,0.5,1)+ 0.6*CHOOSE(IFERROR(INDEX($F$35:$F$39,MATCH("CORNEAL ENDOTHELIAL DISEASE",$E$35:$E$39,0)),0)+1,0,0.8,2,4)+ IF(AND( IFERROR(INDEX($F$35:$F$39,MATCH("DRY EYE DISEASE",$E$35:$E$39,0)),0)>=2, IFERROR(INDEX($F$35:$F$39,MATCH("CORNEAL ENDOTHELIAL DISEASE",$E$35:$E$39,0)),0)>=2 ),0.5,0) ) * IF(B20="NEG ASP",0.75, IF(B20="ZERO ASP",0.78, IF(B20="SPH",0.8, IF(B20="EMV",0.85, IF(B20="EYHANCE",0.9, IF(B20="VIVITY",1, IF(B20="GEME",1.1, IF(B20="ATLISA",1.15, IF(B20="PANOP",1.2,1))))))))) ),1) -> 1.6
B21: SPH | C21: =IF(ABS($H$2+0.15)<=0.1,0,IF(ABS($H$2+0.15)<=0.25,0.4,IF(ABS($H$2+0.15)<=0.5,0.8,1.5))) -> 0.8 | D21: =(ROUND(MAX(0,(($A$2-3)^2)*0.08*C21),2))+C21 -> 0.82 | E21: =ROUND(MIN(10, D21 + ((0.6*$G$2)+(1.2*MAX(0,$E$2-0.2))+(0.6*MAX(0,$F$2-0.2))) * (0.5 + 0.05*D21) ),1) -> 1 | F21: =ROUND(MIN(10, E21+ ( 0.6*CHOOSE(IFERROR(INDEX($F$35:$F$39,MATCH("DRY EYE DISEASE",$E$35:$E$39,0)),0)+1,0,0.5,1.5,3)+ 0.5*CHOOSE(IFERROR(INDEX($F$35:$F$39,MATCH("MACULAR PATHOLOGY",$E$35:$E$39,0)),0)+1,0,0.3,0.8,1.5)+ 0.5*CHOOSE(IFERROR(INDEX($F$35:$F$39,MATCH("DIABETIC RETINOPATHY",$E$35:$E$39,0)),0)+1,0,0.2,0.5,1)+ 0.5*CHOOSE(IFERROR(INDEX($F$35:$F$39,MATCH("GLAUCOMA",$E$35:$E$39,0)),0)+1,0,0.2,0.5,1)+ 0.6*CHOOSE(IFERROR(INDEX($F$35:$F$39,MATCH("CORNEAL ENDOTHELIAL DISEASE",$E$35:$E$39,0)),0)+1,0,0.8,2,4)+ IF(AND( IFERROR(INDEX($F$35:$F$39,MATCH("DRY EYE DISEASE",$E$35:$E$39,0)),0)>=2, IFERROR(INDEX($F$35:$F$39,MATCH("CORNEAL ENDOTHELIAL DISEASE",$E$35:$E$39,0)),0)>=2 ),0.5,0) ) * IF(B21="NEG ASP",0.75, IF(B21="ZERO ASP",0.78, IF(B21="SPH",0.8, IF(B21="EMV",0.85, IF(B21="EYHANCE",0.9, IF(B21="VIVITY",1, IF(B21="GEME",1.1, IF(B21="ATLISA",1.15, IF(B21="PANOP",1.2,1))))))))) ),1) -> 1.6
B22: EMV | C22: 2 | D22: =(ROUND(MAX(0,(($A$2-3)^2)*0.08*C22),2))+C22 -> 2.04 | E22: =ROUND(MIN(10, D22 + ((0.6*$G$2)+(1.2*MAX(0,$E$2-0.2))+(0.6*MAX(0,$F$2-0.2))) * (0.5 + 0.05*D22) ),1) -> 2.2 | F22: =ROUND(MIN(10, E22+ ( 0.6*CHOOSE(IFERROR(INDEX($F$35:$F$39,MATCH("DRY EYE DISEASE",$E$35:$E$39,0)),0)+1,0,0.5,1.5,3)+ 0.5*CHOOSE(IFERROR(INDEX($F$35:$F$39,MATCH("MACULAR PATHOLOGY",$E$35:$E$39,0)),0)+1,0,0.3,0.8,1.5)+ 0.5*CHOOSE(IFERROR(INDEX($F$35:$F$39,MATCH("DIABETIC RETINOPATHY",$E$35:$E$39,0)),0)+1,0,0.2,0.5,1)+ 0.5*CHOOSE(IFERROR(INDEX($F$35:$F$39,MATCH("GLAUCOMA",$E$35:$E$39,0)),0)+1,0,0.2,0.5,1)+ 0.6*CHOOSE(IFERROR(INDEX($F$35:$F$39,MATCH("CORNEAL ENDOTHELIAL DISEASE",$E$35:$E$39,0)),0)+1,0,0.8,2,4)+ IF(AND( IFERROR(INDEX($F$35:$F$39,MATCH("DRY EYE DISEASE",$E$35:$E$39,0)),0)>=2, IFERROR(INDEX($F$35:$F$39,MATCH("CORNEAL ENDOTHELIAL DISEASE",$E$35:$E$39,0)),0)>=2 ),0.5,0) ) * IF(B22="NEG ASP",0.75, IF(B22="ZERO ASP",0.78, IF(B22="SPH",0.8, IF(B22="EMV",0.85, IF(B22="EYHANCE",0.9, IF(B22="VIVITY",1, IF(B22="GEME",1.1, IF(B22="ATLISA",1.15, IF(B22="PANOP",1.2,1))))))))) ),1) -> 2.9
B23: EYHANCE | C23: 2.2 | D23: =(ROUND(MAX(0,(($A$2-3)^2)*0.08*C23),2))+C23 -> 2.24 | E23: =ROUND(MIN(10, D23 + ((0.6*$G$2)+(1.2*MAX(0,$E$2-0.2))+(0.6*MAX(0,$F$2-0.2))) * (0.5 + 0.05*D23) ),1) -> 2.5 | F23: =ROUND(MIN(10, E23+ ( 0.6*CHOOSE(IFERROR(INDEX($F$35:$F$39,MATCH("DRY EYE DISEASE",$E$35:$E$39,0)),0)+1,0,0.5,1.5,3)+ 0.5*CHOOSE(IFERROR(INDEX($F$35:$F$39,MATCH("MACULAR PATHOLOGY",$E$35:$E$39,0)),0)+1,0,0.3,0.8,1.5)+ 0.5*CHOOSE(IFERROR(INDEX($F$35:$F$39,MATCH("DIABETIC RETINOPATHY",$E$35:$E$39,0)),0)+1,0,0.2,0.5,1)+ 0.5*CHOOSE(IFERROR(INDEX($F$35:$F$39,MATCH("GLAUCOMA",$E$35:$E$39,0)),0)+1,0,0.2,0.5,1)+ 0.6*CHOOSE(IFERROR(INDEX($F$35:$F$39,MATCH("CORNEAL ENDOTHELIAL DISEASE",$E$35:$E$39,0)),0)+1,0,0.8,2,4)+ IF(AND( IFERROR(INDEX($F$35:$F$39,MATCH("DRY EYE DISEASE",$E$35:$E$39,0)),0)>=2, IFERROR(INDEX($F$35:$F$39,MATCH("CORNEAL ENDOTHELIAL DISEASE",$E$35:$E$39,0)),0)>=2 ),0.5,0) ) * IF(B23="NEG ASP",0.75, IF(B23="ZERO ASP",0.78, IF(B23="SPH",0.8, IF(B23="EMV",0.85, IF(B23="EYHANCE",0.9, IF(B23="VIVITY",1, IF(B23="GEME",1.1, IF(B23="ATLISA",1.15, IF(B23="PANOP",1.2,1))))))))) ),1) -> 3.2
B24: VIVITY | C24: 3.4 | D24: =(ROUND(MAX(0,(($A$2-3)^2)*0.08*C24),2))+C24 -> 3.47 | E24: =ROUND(MIN(10, D24 + ((0.6*$G$2)+(1.2*MAX(0,$E$2-0.2))+(0.6*MAX(0,$F$2-0.2))) * (0.5 + 0.05*D24) ),1) -> 3.7 | F24: =ROUND(MIN(10, E24+ ( 0.6*CHOOSE(IFERROR(INDEX($F$35:$F$39,MATCH("DRY EYE DISEASE",$E$35:$E$39,0)),0)+1,0,0.5,1.5,3)+ 0.5*CHOOSE(IFERROR(INDEX($F$35:$F$39,MATCH("MACULAR PATHOLOGY",$E$35:$E$39,0)),0)+1,0,0.3,0.8,1.5)+ 0.5*CHOOSE(IFERROR(INDEX($F$35:$F$39,MATCH("DIABETIC RETINOPATHY",$E$35:$E$39,0)),0)+1,0,0.2,0.5,1)+ 0.5*CHOOSE(IFERROR(INDEX($F$35:$F$39,MATCH("GLAUCOMA",$E$35:$E$39,0)),0)+1,0,0.2,0.5,1)+ 0.6*CHOOSE(IFERROR(INDEX($F$35:$F$39,MATCH("CORNEAL ENDOTHELIAL DISEASE",$E$35:$E$39,0)),0)+1,0,0.8,2,4)+ IF(AND( IFERROR(INDEX($F$35:$F$39,MATCH("DRY EYE DISEASE",$E$35:$E$39,0)),0)>=2, IFERROR(INDEX($F$35:$F$39,MATCH("CORNEAL ENDOTHELIAL DISEASE",$E$35:$E$39,0)),0)>=2 ),0.5,0) ) * IF(B24="NEG ASP",0.75, IF(B24="ZERO ASP",0.78, IF(B24="SPH",0.8, IF(B24="EMV",0.85, IF(B24="EYHANCE",0.9, IF(B24="VIVITY",1, IF(B24="GEME",1.1, IF(B24="ATLISA",1.15, IF(B24="PANOP",1.2,1))))))))) ),1) -> 4.5
B25: GEME | C25: 4.6 | D25: =(ROUND(MAX(0,(($A$2-3)^2)*0.08*C25),2))+C25 -> 4.69 | E25: =ROUND(MIN(10, D25 + ((0.6*$G$2)+(1.2*MAX(0,$E$2-0.2))+(0.6*MAX(0,$F$2-0.2))) * (0.5 + 0.05*D25) ),1) -> 4.9 | F25: =ROUND(MIN(10, E25+ ( 0.6*CHOOSE(IFERROR(INDEX($F$35:$F$39,MATCH("DRY EYE DISEASE",$E$35:$E$39,0)),0)+1,0,0.5,1.5,3)+ 0.5*CHOOSE(IFERROR(INDEX($F$35:$F$39,MATCH("MACULAR PATHOLOGY",$E$35:$E$39,0)),0)+1,0,0.3,0.8,1.5)+ 0.5*CHOOSE(IFERROR(INDEX($F$35:$F$39,MATCH("DIABETIC RETINOPATHY",$E$35:$E$39,0)),0)+1,0,0.2,0.5,1)+ 0.5*CHOOSE(IFERROR(INDEX($F$35:$F$39,MATCH("GLAUCOMA",$E$35:$E$39,0)),0)+1,0,0.2,0.5,1)+ 0.6*CHOOSE(IFERROR(INDEX($F$35:$F$39,MATCH("CORNEAL ENDOTHELIAL DISEASE",$E$35:$E$39,0)),0)+1,0,0.8,2,4)+ IF(AND( IFERROR(INDEX($F$35:$F$39,MATCH("DRY EYE DISEASE",$E$35:$E$39,0)),0)>=2, IFERROR(INDEX($F$35:$F$39,MATCH("CORNEAL ENDOTHELIAL DISEASE",$E$35:$E$39,0)),0)>=2 ),0.5,0) ) * IF(B25="NEG ASP",0.75, IF(B25="ZERO ASP",0.78, IF(B25="SPH",0.8, IF(B25="EMV",0.85, IF(B25="EYHANCE",0.9, IF(B25="VIVITY",1, IF(B25="GEME",1.1, IF(B25="ATLISA",1.15, IF(B25="PANOP",1.2,1))))))))) ),1) -> 5.8
B26: ATLISA | C26: 4.9 | D26: =(ROUND(MAX(0,(($A$2-3)^2)*0.08*C26),2))+C26 -> 5 | E26: =ROUND(MIN(10, D26 + ((0.6*$G$2)+(1.2*MAX(0,$E$2-0.2))+(0.6*MAX(0,$F$2-0.2))) * (0.5 + 0.05*D26) ),1) -> 5.3 | F26: =ROUND(MIN(10, E26+ ( 0.6*CHOOSE(IFERROR(INDEX($F$35:$F$39,MATCH("DRY EYE DISEASE",$E$35:$E$39,0)),0)+1,0,0.5,1.5,3)+ 0.5*CHOOSE(IFERROR(INDEX($F$35:$F$39,MATCH("MACULAR PATHOLOGY",$E$35:$E$39,0)),0)+1,0,0.3,0.8,1.5)+ 0.5*CHOOSE(IFERROR(INDEX($F$35:$F$39,MATCH("DIABETIC RETINOPATHY",$E$35:$E$39,0)),0)+1,0,0.2,0.5,1)+ 0.5*CHOOSE(IFERROR(INDEX($F$35:$F$39,MATCH("GLAUCOMA",$E$35:$E$39,0)),0)+1,0,0.2,0.5,1)+ 0.6*CHOOSE(IFERROR(INDEX($F$35:$F$39,MATCH("CORNEAL ENDOTHELIAL DISEASE",$E$35:$E$39,0)),0)+1,0,0.8,2,4)+ IF(AND( IFERROR(INDEX($F$35:$F$39,MATCH("DRY EYE DISEASE",$E$35:$E$39,0)),0)>=2, IFERROR(INDEX($F$35:$F$39,MATCH("CORNEAL ENDOTHELIAL DISEASE",$E$35:$E$39,0)),0)>=2 ),0.5,0) ) * IF(B26="NEG ASP",0.75, IF(B26="ZERO ASP",0.78, IF(B26="SPH",0.8, IF(B26="EMV",0.85, IF(B26="EYHANCE",0.9, IF(B26="VIVITY",1, IF(B26="GEME",1.1, IF(B26="ATLISA",1.15, IF(B26="PANOP",1.2,1))))))))) ),1) -> 6.2
